Workbook

Sheet Balance
A1: PACKAGE | B1: TAXCODE | C1: TIN | D1: NAME | E1: NS10_CODE | F1: NS11_CODE | G1: NS13_CODE | H1: NA1_CODE | I1: YEAR | J1: PERIOD | K1: PTYPE | L1: TYPE | M1: STATE | O1: MAX(T.DATESENT) | P1: SUM010 | Q1: SUM010 | R1: SUM011 | S1: SUM011 | T1: SUM012 | U1: SUM012 | V1: SUM020 | W1: SUM020 | X1: SUM021 | Y1: SUM021 | Z1: SUM022 | AA1: SUM022 | AB1: SUM030 | AC1: SUM030 | AD1: SUM040 | AE1: SUM040 | AF1: SUM050 | AG1: SUM050 | AH1: SUM060 | AI1: SUM060 | AJ1: SUM070 | AK1: SUM070 | AL1: SUM080 | AM1: SUM080 | AN1: SUM090 | AO1: SUM090 | AP1: SUM100 | AQ1: SUM100 | AR1: SUM110 | AS1: SUM110 | AT1: SUM120 | AU1: SUM120 | AV1: SUM130 | AW1: SUM130 | AX1: SUM140 | AY1: SUM140 | AZ1: SUM150 | BA1: SUM150 | BB1: SUM160 | BC1: SUM160 | BD1: SUM170 | BE1: SUM170 | BF1: SUM180 | BG1: SUM180 | BH1: SUM190 | BI1: SUM190 | BJ1: SUM200 | BK1: SUM200 | BL1: SUM210 | BM1: SUM210 | BN1: SUM211 | BO1: SUM211 | BP1: SUM220 | BQ1: SUM220 | BR1: SUM230 | BS1: SUM230 | BT1: SUM240 | BU1: SUM240 | BV1: SUM250 | BW1: SUM250 | BX1: SUM260 | BY1: SUM260 | BZ1: SUM270 | CA1: SUM270 | CB1: SUM280 | CC1: SUM280 | CD1: SUM290 | CE1: SUM290 | CF1: SUM300 | CG1: SUM300 | CH1: SUM310 | CI1: SUM310 | CJ1: SUM320 | CK1: SUM320 | CL1: SUM330 | CM1: SUM330 | CN1: SUM340 | CO1: SUM340 | CP1: SUM350 | CQ1: SUM350 | CR1: SUM360 | CS1: SUM360 | CT1: SUM370 | CU1: SUM370 | CV1: SUM380 | CW1: SUM380 | CX1: SUM390 | CY1: SUM390 | CZ1: SUM400 | DA1: SUM400 | DB1: SUM410 | DC1: SUM410 | DD1: SUM420 | DE1: SUM420 | DF1: SUM430 | DG1: SUM430 | DH1: SUM440 | DI1: SUM440 | DJ1: SUM450 | DK1: SUM450 | DL1: SUM460 | DM1: SUM460 | DN1: SUM470 | DO1: SUM470 | DP1: SUM480 | DQ1: SUM480 | DR1: SUM490 | DS1: SUM490 | DT1: SUM491 | DU1: SUM491 | DV1: SUM500 | DW1: SUM500 | DX1: SUM510 | DY1: SUM510 | DZ1: SUM520 | EA1: SUM520 | EB1: SUM530 | EC1: SUM530 | ED1: SUM540 | EE1: SUM540 | EF1: SUM550 | EG1: SUM550 | EH1: SUM560 | EI1: SUM560 | EJ1: SUM570 | EK1: SUM570 | EL1: SUM580 | EM1: SUM580 | EN1: SUM590 | EO1: SUM590 | EP1: SUM600 | EQ1: SUM600 | ER1: SUM601 | ES1: SUM601 | ET1: SUM602 | EU1: SUM602 | EV1: SUM610 | EW1: SUM610 | EX1: SUM620 | EY1: SUM620 | EZ1: SUM630 | FA1: SUM630 | FB1: SUM640 | FC1: SUM640 | FD1: SUM650 | FE1: SUM650 | FF1: SUM660 | FG1: SUM660 | FH1: SUM670 | FI1: SUM670 | FJ1: SUM680 | FK1: SUM680 | FL1: SUM690 | FM1: SUM690 | FN1: SUM700 | FO1: SUM700 | FP1: SUM710 | FQ1: SUM710 | FR1: SUM720 | FS1: SUM720 | FT1: SUM730 | FU1: SUM730 | FV1: SUM740 | FW1: SUM740 | FX1: SUM750 | FY1: SUM750 | FZ1: SUM760 | GA1: SUM760 | GB1: SUM770 | GC1: SUM770 | GD1: SUM780 | GE1: SUM780
A2: 20006 | B2: 0 | C2: 200240131 | D2: "ANDIJONYOG'MOY" AJ | E2: 3 | F2: 1 | G2: 0 | H2: 1 | I2: 2021 | J2: 4 | K2: N | L2: 2 | M2: 30 | N2: 0 | O2: 44660.822 | P2: 14891463 | Q2: 14891463 | R2: 8241593 | S2: 9098100 | T2: 6649870 | U2: 5793363 | V2: 556007 | W2: 556007 | X2: 556007 | Y2: 556007 | Z2: 0 | AA2: 0 | AB2: 311230 | AC2: 311230 | AD2: 9117 | AE2: 9117 | AF2: 272113 | AG2: 272113 | AL2: 30000 | AM2: 30000 | AN2: 136832 | AO2: 136832 | AP2: 263866 | AQ2: 269165 | AR2: 1906630 | AS2: 2067215 | AV2: 9268428 | AW2: 8577805 | AX2: 24531306 | AY2: 12162334 | AZ2: 5022094 | BA2: 6156656 | BD2: 19509212 | BE2: 6005678 | BJ2: 29627260 | BK2: 12327260 | BL2: 12443201 | BM2: 66922943 | BP2: 336240 | BQ2: 63486711 | BV2: 6521 | BW2: 6652 | BX2: 8649559 | BY2: 2773870 | BZ2: 3049127 | CA2: 315110 | CB2: 4137 | CC2: 4711 | CH2: 397617 | CI2: 335889 | CJ2: 585490 | CK2: 546670 | CN2: 1 | CP2: 3417 | CQ2: 3535 | CR2: 582072 | CS2: 543135 | CT2: 296711 | CU2: 291961 | CX2: 67483968 | CY2: 92251168 | CZ2: 76752396 | DA2: 100828973 | DB2: 1833238 | DC2: 1833238 | DF2: 3402704 | DG2: 3402704 | DJ2: -12319063 | DK2: -12313502 | DL2: 511230 | DM2: 511230 | DP2: -6571891 | DQ2: -6566330 | DR2: 30642279 | DS2: 32607213 | EL2: 30642279 | EM2: 32607213 | EP2: 50094788 | EQ2: 74788090 | ER2: 10942777 | ES2: 38128531 | EV2: 7913339 | EW2: 30667667 | FH2: 1655 | FI2: 416759 | FJ2: 250654 | FK2: 2893455 | FN2: 99218 | FO2: 244921 | FP2: 886565 | FQ2: 885581 | FR2: 1154369 | FS2: 1737003 | FT2: 15745000 | FU2: 3931000 | FV2: 23407011 | FW2: 32728559 | FZ2: 636977 | GA2: 1283145 | GB2: 80737067 | GC2: 107395303 | GD2: 74165176 | GE2: 100828973
A3: 20006 | B3: 0 | C3: 200240131 | D3: "ANDIJONYOG'MOY" AJ | E3: 3 | F3: 1 | G3: 0 | H3: 1 | I3: 2020 | J3: 4 | K3: N | L3: 1 | M3: 30 | N3: 0 | O3: 44240.648 | P3: 15160699 | Q3: 14891463 | R3: 7565795 | S3: 8241711 | T3: 7594904 | U3: 6649752 | V3: 556007 | W3: 556007 | X3: 444806 | Y3: 556007 | Z3: 111201 | AA3: 0 | AB3: 325356 | AC3: 311230 | AD3: 23243 | AE3: 9117 | AF3: 272113 | AG3: 272113 | AL3: 30000 | AM3: 30000 | AN3: 136832 | AO3: 136832 | AP3: 432398 | AQ3: 263867 | AR3: 1556214 | AS3: 1906629 | AV3: 10156905 | AW3: 9268310 | AX3: 22172154 | AY3: 24433848 | AZ3: 6924978 | BA3: 5022149 | BD3: 15247176 | BE3: 19411699 | BH3: 2920 | BJ3: 28899167 | BK3: 29744238 | BL3: 5477009 | BM3: 12632393 | BN3: 785597 | BO3: 622280 | BP3: 857301 | BQ3: 336240 | BV3: 31599 | BW3: 6520 | BX3: 834064 | BY3: 8535906 | BZ3: 1401435 | CA3: 2660945 | CB3: 4137 | CC3: 4594 | CH3: 2348473 | CI3: 1088188 | CJ3: 25208 | CK3: 8454 | CN3: 16659 | CP3: 3101 | CQ3: 3417 | CR3: 5448 | CS3: 5037 | CT3: 531046 | CU3: 296711 | CX3: 57107504 | CY3: 67115644 | CZ3: 67264409 | DA3: 76383954 | DB3: 1833238 | DC3: 1833238 | DF3: 3433449 | DG3: 3390157 | DJ3: 2342361 | DK3: -12453753 | DL3: 262047 | DM3: 478723 | DP3: 7871095 | DQ3: -6751635 | DR3: 29569418 | DS3: 33152642 | EL3: 29569418 | EM3: 33152642 | EP3: 29823896 | EQ3: 49982947 | ER3: 8308735 | ES3: 10830936 | ET3: 100184 | EU3: 72240 | EV3: 3957634 | EW3: 7456941 | FH3: 6517 | FI3: 1655 | FJ3: 138090 | FK3: 244060 | FN3: 193310 | FP3: 131444 | FQ3: 886565 | FR3: 859826 | FS3: 1149170 | FT3: 21400000 | FU3: 15745000 | FV3: 115161 | FW3: 23407011 | FZ3: 3021914 | GA3: 1092545 | GB3: 59393314 | GC3: 83135589 | GD3: 67264409 | GE3: 76383954
A4: 20006 | B4: 0 | C4: 200240131 | D4: "ANDIJONYOG'MOY" AJ | E4: 3 | F4: 1 | G4: 0 | H4: 1 | I4: 2019 | J4: 4 | K4: N | L4: 1 | M4: 30 | N4: 0 | O4: 43875.627 | P4: 12335367 | Q4: 14370848 | R4: 7184838 | S4: 7175500 | T4: 5150529 | U4: 7195348 | V4: 556007 | W4: 556007 | X4: 333604 | Y4: 444806 | Z4: 222403 | AA4: 111201 | AB4: 325356 | AC4: 325356 | AD4: 23243 | AE4: 23243 | AF4: 272113 | AG4: 272113 | AL4: 30000 | AM4: 30000 | AN4: 237348 | AO4: 127523 | AP4: 275234 | AQ4: 401843 | AR4: 1266868 | AS4: 1556214 | AV4: 7477738 | AW4: 9717485 | AX4: 11734265 | AY4: 22172154 | AZ4: 7196771 | BA4: 6924978 | BD4: 4537494 | BE4: 15247176 | BH4: 20832 | BI4: 2920 | BJ4: 26899637 | BK4: 28899167 | BL4: 6124106 | BM4: 5477009 | BN4: 610583 | BO4: 785597 | BP4: 1839893 | BQ4: 857301 | BV4: 35497 | BW4: 31599 | BX4: 1220116 | BY4: 834064 | BZ4: 692024 | CA4: 1401435 | CC4: 4137 | CH4: 2336576 | CI4: 2348473 | CJ4: 863321 | CK4: 25208 | CN4: 23612 | CO4: 16659 | CP4: 832163 | CQ4: 3101 | CR4: 7546 | CS4: 5448 | CT4: 1362271 | CU4: 531046 | CX4: 47004432 | CY4: 57107504 | CZ4: 54482170 | DA4: 66824989 | DB4: 1833238 | DC4: 1833238 | DF4: 3529736 | DG4: 2994029 | DJ4: 2063462 | DK4: 2342361 | DL4: 100798 | DM4: 262047 | DP4: 7527234 | DQ4: 7431675 | DR4: 28001815 | DS4: 29569418 | EL4: 28001815 | EM4: 29569418 | EP4: 18953121 | EQ4: 29823896 | ER4: 3300023 | ES4: 8308735 | ET4: 53590 | EU4: 100184 | EV4: 764985 | EW4: 3957634 | FH4: 43485 | FI4: 6517 | FJ4: 73580 | FK4: 138090 | FN4: 699074 | FO4: 193310 | FP4: 82224 | FQ4: 131444 | FR4: 507432 | FS4: 859826 | FT4: 15594752 | FU4: 21400000 | FV4: 58346 | FW4: 115161 | FZ4: 1129243 | GA4: 3021914 | GB4: 46954936 | GC4: 59393314 | GD4: 54482170 | GE4: 66824989
A5: 20006 | B5: 0 | C5: 200240131 | D5: "ANDIJONYOG'MOY" AJ | E5: 3 | F5: 1 | G5: 0 | H5: 1 | I5: 2018 | J5: 4 | K5: N | L5: 1 | M5: 30 | N5: 0 | O5: 43508.483 | P5: 11101851 | Q5: 11540839 | R5: 6422483 | S5: 6775850 | T5: 4679368 | U5: 4764989 | V5: 556007 | W5: 556007 | X5: 333604 | Y5: 333604 | Z5: 222403 | AA5: 222403 | AB5: 345057 | AC5: 325356 | AD5: 21694 | AE5: 23243 | AF5: 272113 | AG5: 272113 | AL5: 51250 | AM5: 30000 | AN5: 561985 | AO5: 227345 | AP5: 128798 | AQ5: 258400 | AR5: 84711 | AS5: 1266868 | AV5: 6022322 | AW5: 7065361 | AX5: 7450861 | AY5: 11734265 | AZ5: 4662038 | BA5: 7196771 | BD5: 2788823 | BE5: 4537494 | BH5: 25639 | BI5: 20832 | BJ5: 27089450 | BK5: 26899637 | BL5: 2750262 | BM5: 6124106 | BN5: 650380 | BO5: 610583 | BP5: 415796 | BQ5: 1839893 | BV5: 28118 | BW5: 35497 | BX5: 501253 | BY5: 1220116 | BZ5: 102081 | CA5: 692024 | CH5: 1703014 | CI5: 2336576 | CJ5: 273182 | CK5: 863321 | CN5: 265873 | CO5: 23612 | CP5: 2649 | CQ5: 832163 | CR5: 4660 | CS5: 7546 | CT5: 227223 | CU5: 1362271 | CX5: 37816617 | CY5: 47004432 | CZ5: 43838939 | DA5: 54069793 | DB5: 1833238 | DC5: 1833238 | DF5: 3349287 | DG5: 3117359 | DJ5: 1119975 | DK5: 2063462 | DM5: 100798 | DP5: 6302500 | DQ5: 7114857 | DR5: 28571453 | DS5: 28001815 | EL5: 28571453 | EM5: 28001815 | EP5: 8964986 | EQ5: 18953121 | ER5: 5314486 | ES5: 3300023 | ET5: 68898 | EU5: 53590 | EV5: 2673586 | EW5: 764985 | FH5: 64591 | FI5: 43485 | FJ5: 1128237 | FK5: 73580 | FN5: 468669 | FO5: 699074 | FP5: 113691 | FQ5: 82224 | FR5: 494076 | FS5: 507432 | FT5: 3650500 | FU5: 15594752 | FW5: 58346 | FZ5: 371636 | GA5: 1129243 | GB5: 37536439 | GC5: 46954936 | GD5: 43838939 | GE5: 54069793
A6: 20006 | B6: 0 | C6: 200244553 | D6: "ASAKA YOG'" AJ | E6: 3 | F6: 15 | G6: 0 | H6: 1 | I6: 2021 | J6: 4 | K6: N | L6: 2 | M6: 30 | N6: 0 | O6: 44606.898 | P6: 26237285 | Q6: 26170297 | R6: 13742606 | S6: 14786616 | T6: 12494679 | U6: 11383681 | V6: 14000 | W6: 14000 | X6: 14000 | Y6: 14000 | Z6: 0 | AA6: 0 | AB6: 414991 | AC6: 414991 | AD6: 5000 | AE6: 5000 | AF6: 11000 | AG6: 11000 | AL6: 398991 | AM6: 398991 | AR6: 2262786 | AS6: 2372291 | AV6: 15172456 | AW6: 14170963 | AX6: 24715469 | AY6: 20709898 | AZ6: 12313497 | BA6: 7908816 | BC6: 342483 | BD6: 12401972 | BE6: 12458599 | BL6: 14504336 | BM6: 14251183 | BP6: 1929624 | BQ6: 159965 | BX6: 10920306 | BY6: 13477525 | BZ6: 1578988 | CA6: 416440 | CB6: 5 | CC6: 1266 | CF6: 17878 | CG6: 14663 | CH6: 57535 | CI6: 181324 | CJ6: 1899 | CK6: 1316 | CN6: 303 | CO6: 1232 | CP6: 84 | CQ6: 84 | CR6: 1512 | CS6: 0 | CX6: 39221704 | CY6: 34962397 | CZ6: 54394160 | DA6: 49133360 | DB6: 2747464 | DC6: 2747464 | DF6: 9133488 | DG6: 9101428 | DJ6: -2026350 | DK6: -4856219 | DL6: 9362 | DM6: 9362 | DP6: 9863964 | DQ6: 7002035 | DR6: 25423419 | DS6: 12437863 | DT6: 4632169 | DU6: 4457863 | DV6: 4632169 | DW6: 4457863 | EJ6: 20670000 | EK6: 7980000 | EL6: 121250 | EM6: 0 | EP6: 19106777 | EQ6: 29693462 | ER6: 14726777 | ES6: 29693462 | EV6: 12005655 | EW6: 18023530 | EZ6: 169210 | FA6: 0 | FH6: 518979 | FI6: 5060002 | FJ6: 94511 | FK6: 1260084 | FN6: 94118 | FO6: 168533 | FR6: 1562043 | FS6: 1938283 | FT6: 4100000 | FU6: 0 | FV6: 280000 | FW6: 0 | FZ6: 282261 | GA6: 3243030 | GB6: 44530196 | GC6: 42131325 | GD6: 54394160 | GE6: 49133360
A7: 20006 | B7: 0 | C7: 200244553 | D7: "ASAKA YOG'" AJ | E7: 3 | F7: 15 | G7: 0 | H7: 1 | I7: 2020 | J7: 4 | K7: N | L7: 1 | M7: 30 | N7: 0 | O7: 44247.95 | P7: 23467083 | Q7: 26237285 | R7: 12688746 | S7: 13742606 | T7: 10778337 | U7: 12494679 | V7: 14000 | W7: 14000 | X7: 14000 | Y7: 14000 | Z7: 0 | AA7: 0 | AB7: 416606 | AC7: 414991 | AD7: 6615 | AE7: 5000 | AF7: 11000 | AG7: 11000 | AL7: 398991 | AM7: 398991 | AP7: 2125 | AR7: 1500404 | AS7: 2262786 | AV7: 12697472 | AW7: 15172456 | AX7: 21831719 | AY7: 24715469 | AZ7: 8580879 | BA7: 12313497 | BD7: 13250840 | BE7: 12401972 | BJ7: 920076 | BK7: 0 | BL7: 9060302 | BM7: 14504336 | BP7: 1454162 | BQ7: 1929624 | BX7: 6044188 | BY7: 10920306 | BZ7: 1318393 | CA7: 1578988 | CB7: 5 | CC7: 5 | CF7: 51757 | CG7: 17878 | CH7: 191797 | CI7: 57535 | CJ7: 4114 | CK7: 1899 | CN7: 496 | CO7: 303 | CP7: 76 | CQ7: 84 | CR7: 3542 | CS7: 1512 | CT7: 68000 | CU7: 0 | CX7: 31884211 | CY7: 39221704 | CZ7: 44581683 | DA7: 54394160 | DB7: 2747464 | DC7: 2747464 | DF7: 6072144 | DG7: 9133488 | DJ7: 4289308 | DK7: -2026350 | DM7: 9362 | DP7: 13108916 | DQ7: 9863964 | DR7: 5170448 | DS7: 25423419 | DT7: 5049198 | DU7: 4632169 | DV7: 5049198 | DW7: 4632169 | EK7: 20670000 | EL7: 121250 | EM7: 121250 | EP7: 26302319 | EQ7: 19106777 | ER7: 5272319 | ES7: 14726777 | EV7: 3282688 | EW7: 12005655 | EZ7: 110397 | FA7: 169210 | FH7: 538362 | FI7: 518979 | FJ7: 9640 | FK7: 94511 | FN7: 159000 | FO7: 94118 | FR7: 827737 | FS7: 1562043 | FT7: 20750000 | FU7: 4100000 | FV7: 280000 | FW7: 280000 | FZ7: 344495 | GA7: 282261 | GB7: 31472767 | GC7: 44530196 | GD7: 44581683 | GE7: 54394160
A8: 20006 | B8: 0 | C8: 200244553 | D8: "ASAKA YOG'" AJ | E8: 3 | F8: 15 | G8: 0 | H8: 1 | I8: 2019 | J8: 4 | K8: N | L8: 2 | M8: 30 | N8: 0 | O8: 43885.466 | P8: 19883971 | Q8: 22051424 | R8: 11044042 | S8: 11949849 | T8: 8839929 | U8: 10101575 | V8: 14000 | W8: 14000 | X8: 14000 | Y8: 14000 | Z8: 0 | AA8: 0 | AB8: 385927 | AC8: 416606 | AD8: 6615 | AE8: 6615 | AF8: 11000 | AG8: 11000 | AL8: 368312 | AM8: 398991 | AP8: 1097442 | AQ8: 2125 | AR8: 1254566 | AS8: 1500404 | AV8: 11577864 | AW8: 12020710 | AX8: 15470495 | AY8: 21831719 | AZ8: 9366375 | BA8: 8580879 | BD8: 6104120 | BE8: 13250840 | BH8: 4000 | BI8: 0 | BJ8: 1236408 | BK8: 920076 | BL8: 8323255 | BM8: 9060302 | BP8: 322830 | BQ8: 1454162 | BX8: 7279458 | BY8: 6044188 | BZ8: 556009 | CA8: 1318393 | CB8: 5 | CC8: 5 | CF8: 80921 | CG8: 51757 | CH8: 84032 | CI8: 191797 | CJ8: 1880557 | CK8: 4114 | CN8: 3488 | CO8: 496 | CP8: 270791 | CQ8: 76 | CR8: 1606278 | CS8: 3542 | CT8: 1000000 | CU8: 68000 | CX8: 27914715 | CY8: 31884211 | CZ8: 39492579 | DA8: 43904921 | DB8: 2747464 | DC8: 2747464 | DF8: 5423139 | DG8: 5395382 | DJ8: 3907136 | DK8: 4289308 | DL8: 916348 | DN8: 600000 | DP8: 13594087 | DQ8: 12432154 | DR8: 4798669 | DS8: 5170448 | DT8: 4677419 | DU8: 5049198 | DV8: 4677419 | DW8: 5049198 | EL8: 121250 | EM8: 121250 | EP8: 21099823 | EQ8: 26302319 | ER8: 4045823 | ES8: 5272319 | EV8: 2403040 | EW8: 3282688 | FA8: 110397 | FH8: 9486 | FI8: 538362 | FJ8: 64260 | FK8: 9640 | FN8: 732175 | FO8: 159000 | FR8: 579228 | FS8: 827737 | FT8: 17054000 | FU8: 20750000 | FW8: 280000 | FZ8: 257634 | GA8: 344495 | GB8: 25898492 | GC8: 31472767 | GD8: 39492579 | GE8: 43904921
A9: 20006 | B9: 0 | C9: 200244553 | D9: "ASAKA YOG'" AJ | E9: 3 | F9: 15 | G9: 0 | H9: 1 | I9: 2018 | J9: 4 | K9: N | L9: 1 | M9: 30 | N9: 0 | O9: 43507.649 | P9: 17272650 | Q9: 18767080 | R9: 9449550 | S9: 10437463 | T9: 7823100 | U9: 8329617 | V9: 14000 | W9: 14000 | X9: 14000 | Y9: 14000 | Z9: 0 | AA9: 0 | AB9: 432177 | AC9: 385927 | AD9: 6615 | AE9: 6615 | AF9: 11000 | AG9: 11000 | AL9: 414562 | AM9: 368312 | AP9: 27975 | AQ9: 1097442 | AR9: 949618 | AS9: 1254566 | AV9: 9232870 | AW9: 11067552 | AX9: 6116393 | AY9: 15470495 | AZ9: 4115249 | BA9: 9366375 | BD9: 2001144 | BE9: 6104120 | BH9: 16525 | BI9: 4000 | BJ9: 2627728 | BK9: 1236408 | BL9: 4462160 | BM9: 8323255 | BP9: 20911 | BQ9: 322830 | BX9: 4150542 | BY9: 7279458 | BZ9: 82796 | CA9: 556009 | CB9: 0 | CC9: 5 | CF9: 56670 | CG9: 80921 | CH9: 151241 | CI9: 84032 | CJ9: 337865 | CK9: 1880557 | CN9: 244633 | CO9: 3488 | CQ9: 270791 | CR9: 93232 | CS9: 1606278 | CU9: 1000000 | CX9: 13560671 | CY9: 27914715 | CZ9: 22793541 | DA9: 38982267 | DB9: 2747464 | DC9: 2747464 | DF9: 4860058 | DG9: 4912827 | DJ9: 2055379 | DK9: 3907136 | DL9: 916348 | DM9: 916348 | DO9: 600000 | DP9: 10579249 | DQ9: 13083775 | DR9: 5549671 | DS9: 4798669 | DT9: 5307171 | DU9: 4677419 | DV9: 5307171 | DW9: 4677419 | EL9: 242500 | EM9: 121250 | EP9: 6664621 | EQ9: 21099823 | ER9: 5210621 | ES9: 4045823 | EV9: 2394477 | EW9: 2403040 | FH9: 375662 | FI9: 9486 | FJ9: 998758 | FK9: 64260 | FN9: 541012 | FO9: 732175 | FR9: 360536 | FS9: 579228 | FT9: 1454000 | FU9: 17054000 | FZ9: 540176 | GA9: 257634 | GB9: 12214292 | GC9: 25898492 | GD9: 22793541 | GE9: 38982267
A10: 20006 | B10: 0 | C10: 200323067 | D10: "GULISTON EKSTRAKT-YOG'" AJ | E10: 24 | F10: 10 | G10: 2 | H10: 1 | I10: 2021 | J10: 4 | K10: N | L10: 2 | M10: 30 | N10: 0 | O10: 44621.623 | P10: 22697474 | Q10: 23314015 | R10: 16631362 | S10: 18409072 | T10: 6066112 | U10: 4904943 | Z10: 0 | AB10: 546150 | AC10: 546150 | AD10: 51 | AE10: 51 | AF10: 546099 | AG10: 546099 | AN10: 53751 | AO10: 53751 | AP10: 3728002 | AQ10: 3728002 | AR10: 1332940 | AS10: 1477780 | AV10: 11726955 | AW10: 10710626 | AX10: 14952895 | AY10: 11699951 | AZ10: 8992752 | BA10: 7054057 | BB10: 4766559 | BC10: 4480498 | BD10: 1029495 | BE10: 1307 | BF10: 164089 | BG10: 164089 | BH10: 13719893 | BI10: 13719893 | BJ10: 26217392 | BK10: 26217392 | BL10: 29634491 | BM10: 12793429 | BP10: 1403961 | BQ10: 1795605 | BT10: 363 | BU10: 363 | BV10: 40039 | BW10: 85478 | BX10: 22863454 | BY10: 5200106 | BZ10: 933770 | CA10: 1363617 | CC10: 164050 | CF10: 164608 | CG10: 101246 | CH10: 4228296 | CI10: 4082964 | CJ10: 14758 | CK10: 10295 | CN10: 14106 | CO10: 9643 | CP10: 652 | CQ10: 652 | CV10: 23346 | CW10: 23346 | CX10: 84562775 | CY10: 64464306 | CZ10: 96289730 | DA10: 75174932 | DB10: 986966 | DC10: 986966 | DD10: 993961 | DE10: 993961 | DF10: 5697194 | DG10: 5904769 | DJ10: 44889 | DK10: -7028738 | DP10: 7723010 | DQ10: 856958 | DR10: 29814057 | DS10: 29814057 | DT10: 4375439 | DU10: 4375439 | EL10: 25438618 | EM10: 25438618 | EN10: 4375439 | EO10: 4375439 | EP10: 58752663 | EQ10: 44503917 | ER10: 16968384 | ES10: 15818850 | EV10: 1154824 | EW10: 1381522 | FB10: 1220261 | FC10: 1220261 | FH10: 7371399 | FI10: 1058361 | FJ10: 510135 | FK10: 2134850 | FL10: 10 | FM10: 10 | FN10: 225579 | FO10: 169400 | FP10: 5424739 | FQ10: 5361499 | FR10: 460169 | FS10: 1774440 | FT10: 32291906 | FU10: 19192694 | FV10: 8272112 | FW10: 8272112 | FZ10: 1821529 | GA10: 3938768 | GB10: 88566720 | GC10: 74317974 | GD10: 96289730 | GE10: 75174932
A11: 20006 | B11: 0 | C11: 200323067 | D11: "GULISTON EKSTRAKT-YOG'" AJ | E11: 24 | F11: 10 | G11: 2 | H11: 1 | I11: 2020 | J11: 4 | K11: N | L11: 2 | M11: 30 | N11: 0 | O11: 44596.374 | P11: 21196752 | Q11: 22697474 | R11: 14286423 | S11: 16631362 | T11: 6910329 | U11: 6066112 | Z11: 0 | AB11: 546150 | AC11: 546150 | AD11: 51 | AE11: 51 | AF11: 546099 | AG11: 546099 | AN11: 53751 | AO11: 53751 | AP11: 3743002 | AQ11: 3728002 | AR11: 1616025 | AS11: 1332940 | AV11: 12869257 | AW11: 11726955 | AX11: 40270414 | AY11: 14952895 | AZ11: 15107486 | BA11: 8992752 | BB11: 315300 | BC11: 4766559 | BD11: 24683539 | BE11: 1029495 | BF11: 164089 | BG11: 164089 | BH11: 10950000 | BI11: 13719893 | BJ11: 26217477 | BK11: 26217392 | BL11: 12929570 | BM11: 29634491 | BP11: 1061166 | BQ11: 1403961 | BU11: 363 | BV11: 12346 | BW11: 40039 | BX11: 5627229 | BY11: 22863454 | BZ11: 2211307.3 | CA11: 933770 | CF11: 15241 | CG11: 164608 | CH11: 4002281 | CI11: 4228296 | CJ11: 52090 | CK11: 14758 | CO11: 14106 | CP11: 52090 | CQ11: 652 | CV11: 23346 | CW11: 23346 | CX11: 90442897 | CY11: 84562775 | CZ11: 1.0331215e+08 | DA11: 96289730 | DB11: 986966 | DC11: 986966 | DD11: 993961 | DE11: 993961 | DF11: 5137538 | DG11: 5697194 | DJ11: 16000542 | DK11: 44889 | DP11: 23119007 | DQ11: 7723010 | DR11: 25910546 | DS11: 29814057 | DT11: 2573744 | DU11: 4375439 | EL11: 23336802 | EM11: 25438618 | EN11: 2573744 | EO11: 4375439 | EP11: 54282601 | EQ11: 58752663 | ER11: 18818349 | ES11: 16968384 | EV11: 3786546 | EW11: 1154824 | FB11: 875607.56 | FC11: 1220261 | FH11: 2629151 | FI11: 7371399 | FJ11: 63926.74 | FK11: 510135 | FL11: 10 | FM11: 10 | FN11: 406076 | FO11: 225579 | FP11: 7747100 | FQ11: 5424739 | FR11: 1622297 | FS11: 460169 | FT11: 27000000 | FU11: 32291906 | FV11: 7588645 | FW11: 8272112 | FZ11: 2563242 | GA11: 1821529 | GB11: 80193147 | GC11: 88566720 | GD11: 1.0331215e+08 | GE11: 96289730
A12: 20006 | B12: 0 | C12: 200323067 | D12: "GULISTON EKSTRAKT-YOG'" AJ | E12: 24 | F12: 10 | G12: 2 | H12: 1 | I12: 2019 | J12: 4 | K12: N | L12: 2 | M12: 30 | N12: 0 | O12: 44594.979 | P12: 20668479 | Q12: 21196752 | R12: 13026810 | S12: 14286423 | T12: 7641669 | U12: 6910329 | AB12: 636963 | AC12: 546150 | AD12: 51 | AE12: 51 | AF12: 636912 | AG12: 546099 | AN12: 60791 | AO12: 53751 | AP12: 1343828 | AQ12: 3743002 | AR12: 1907821 | AS12: 1616025 | AV12: 11591072 | AW12: 12869257 | AX12: 26705266 | AY12: 40270414 | AZ12: 7956790 | BA12: 15107486 | BB12: 39283 | BC12: 315300 | BD12: 18507049 | BE12: 24683539 | BF12: 202144 | BG12: 164089 | BI12: 10950000 | BJ12: 26218995 | BK12: 26217477 | BL12: 8416276 | BM12: 12929570 | BN12: 271889 | BP12: 722163 | BQ12: 1061166 | BV12: 3515 | BW12: 12346 | BX12: 5535509 | BY12: 5627229 | BZ12: 444132 | CA12: 2211307.3 | CF12: 13411 | CG12: 15241 | CH12: 1697546 | CI12: 4002281 | CJ12: 1444811 | CK12: 52090 | CN12: 1141965 | CP12: 302846 | CQ12: 52090 | CV12: 23346 | CW12: 23346 | CX12: 62808694 | CY12: 90442897 | CZ12: 74399766 | DA12: 1.0331215e+08 | DB12: 986966 | DC12: 986966 | DD12: 993961 | DE12: 993961 | DF12: 4341974 | DG12: 5137538 | DJ12: 25140915 | DK12: 16000542 | DP12: 31463816 | DQ12: 23119007 | DR12: 20416519 | DS12: 25910546 | DU12: 2573744 | EL12: 20416519 | EM12: 23336802 | EO12: 2573744 | EP12: 22519431 | EQ12: 54282601 | ER12: 3915435 | ES12: 18818349 | EV12: 322577 | EW12: 3786546 | FC12: 875607.56 | FF12: 1234677 | FH12: 47634 | FI12: 2629151 | FJ12: 378988 | FK12: 63926.74 | FM12: 10 | FN12: 1113039 | FO12: 406076 | FP12: 106751 | FQ12: 7747100 | FR12: 1213233 | FS12: 1622297 | FT12: 10996354 | FU12: 27000000 | FV12: 6372965 | FW12: 7588645 | FZ12: 733213 | GA12: 2563242 | GB12: 42935950 | GC12: 80193147 | GD12: 74399766 | GE12: 1.0331215e+08
A13: 20006 | B13: 0 | C13: 200323067 | D13: "GULISTON EKSTRAKT-YOG'" AJ | E13: 24 | F13: 10 | G13: 2 | H13: 1 | I13: 2018 | J13: 4 | K13: N | L13: 2 | M13: 30 | N13: 0 | O13: 43620.446 | P13: 17952322 | Q13: 19833890 | R13: 11258028 | S13: 12550134 | T13: 6694294 | U13: 7283756 | AB13: 737864 | AC13: 636963 | AD13: 32772 | AE13: 51 | AF13: 705092 | AG13: 636912 | AN13: 125691 | AO13: 60791 | AP13: 1313477 | AQ13: 1343828 | AR13: 1670039 | AS13: 1907821 | AV13: 10541365 | AW13: 11233159 | AX13: 12723107 | AY13: 26705266 | AZ13: 5608314 | BA13: 7956790 | BB13: 321973 | BC13: 39283 | BD13: 6792820 | BE13: 18507049 | BG13: 202144 | BH13: 206633 | BI13: 0 | BJ13: 25489415 | BK13: 26218995 | BL13: 6602767 | BM13: 8416276 | BN13: 21905 | BO13: 271889 | BP13: 2939786 | BQ13: 722163 | BV13: 2792 | BW13: 3515 | BX13: 2674689 | BY13: 5535509 | BZ13: 367210 | CA13: 444132 | CB13: 6 | CC13: 0 | CF13: 30248 | CG13: 13411 | CH13: 588036 | CI13: 1697546 | CJ13: 235456 | CK13: 1444811 | CN13: 14870 | CO13: 1141965 | CP13: 8502 | CQ13: 302846 | CR13: 212084 | CS13: 0 | CT13: 21500 | CU13: 0 | CV13: 23346 | CW13: 23346 | CX13: 45302224 | CY13: 62808694 | CZ13: 55843589 | DA13: 74041853 | DB13: 986966 | DC13: 986966 | DD13: 993961 | DE13: 993961 | DF13: 3952380 | DG13: 3984061 | DJ13: 10002726 | DK13: 25140915 | DP13: 15936033 | DQ13: 31105903 | DR13: 21365658 | DS13: 20416519 | EL13: 21365658 | EM13: 20416519 | EP13: 18541898 | EQ13: 22519431 | ER13: 5817543 | ES13: 3915435 | EV13: 3227911 | EW13: 322577 | FF13: 100817 | FG13: 1234677 | FH13: 5296 | FI13: 47634 | FJ13: 655534 | FK13: 378988 | FN13: 499702 | FO13: 1113039 | FP13: 226638 | FQ13: 106751 | FR13: 211634 | FS13: 1213233 | FT13: 6700000 | FU13: 10996354 | FV13: 5923538 | FW13: 6372965 | FZ13: 990828 | GA13: 733213 | GB13: 39907556 | GC13: 42935950 | GD13: 55843589 | GE13: 74041853
A14: 20006 | B14: 0 | C14: 200466854 | D14: "YANGIYO'L YOG'-MOY" AJ | E14: 27 | F14: 22 | G14: 0 | H14: 8 | I14: 2021 | J14: 4 | K14: N | L14: 1 | M14: 30 | N14: 0 | O14: 44624.645 | P14: 46482344 | Q14: 46528972 | R14: 29880530 | S14: 31474475 | T14: 16601814 | U14: 15054497 | V14: 74882 | W14: 74882 | Z14: 74882 | AA14: 74882 | AB14: 1551476 | AC14: 1551476 | AD14: 536 | AE14: 536 | AL14: 1550940 | AM14: 1550940 | AN14: 5761806 | AO14: 7298353 | AP14: 159559 | AQ14: 241658 | AR14: 295354 | AS14: 202155 | AV14: 24444891 | AW14: 24423021 | AX14: 15336232 | AY14: 14845788 | AZ14: 10649173 | BA14: 7757475 | BB14: 12145 | BC14: 0 | BD14: 4674914 | BE14: 7088313 | BH14: 310950 | BI14: 415258 | BL14: 13343480 | BM14: 12266351 | BN14: 997445 | BO14: 917923 | BP14: 2230541 | BQ14: 4800787 | BX14: 7856469 | BY14: 3320560 | BZ14: 1368334 | CA14: 2088283 | CB14: 19046 | CC14: 9657 | CF14: 299926 | CG14: 252860 | CH14: 1569164 | CI14: 1794204 | CJ14: 8866295 | CK14: 2071749 | CN14: 30281 | CO14: 662023 | CP14: 8500722 | CQ14: 70925 | CR14: 335292 | CS14: 1338801 | CT14: 157711 | CU14: 37944 | CV14: 1982 | CW14: 1760 | CX14: 38016650 | CY14: 29638850 | CZ14: 62461541 | DA14: 54061871 | DB14: 8452563 | DC14: 8452563 | DD14: 13982173 | DE14: 13982173 | DF14: 12802057 | DG14: 12757918 | DJ14: 14115899 | DK14: 8435898 | DP14: 49352692 | DQ14: 43628552 | EP14: 13108849 | EQ14: 10433319 | ER14: 3107284 | ES14: 2431754 | EV14: 853490 | EW14: 899385 | FH14: 41121 | FI14: 52594 | FJ14: 365795 | FK14: 173450 | FN14: 265522 | FO14: 193985 | FP14: 894890 | FQ14: 395756 | FR14: 610078 | FS14: 629797 | FT14: 10001565 | FU14: 8001565 | FZ14: 76388 | GA14: 86787 | GB14: 13108849 | GC14: 10433319 | GD14: 62461541 | GE14: 54061871
A15: 20006 | B15: 0 | C15: 200466854 | D15: "YANGIYO'L YOG'-MOY" AJ | E15: 27 | F15: 22 | G15: 0 | H15: 8 | I15: 2020 | J15: 4 | K15: N | L15: 1 | M15: 30 | N15: 0 | O15: 44264.45 | P15: 43742333 | Q15: 46482344 | R15: 26813671 | S15: 29880530 | T15: 16928662 | U15: 16601814 | V15: 74882 | W15: 74882 | Z15: 74882 | AA15: 74882 | AB15: 1551476 | AC15: 1551476 | AD15: 536 | AE15: 536 | AL15: 1550940 | AM15: 1550940 | AN15: 1586341 | AO15: 5761806 | AP15: 77451 | AQ15: 159559 | AR15: 401169 | AS15: 295354 | AV15: 20619981 | AW15: 24444891 | AX15: 30951383 | AY15: 15336232 | AZ15: 7811552 | BA15: 10649173 | BB15: 77080 | BC15: 12145 | BD15: 23062751 | BE15: 4674914 | BH15: 388499 | BI15: 310950 | BL15: 10350372 | BM15: 13343480 | BO15: 991032 | BP15: 762559 | BQ15: 2230541 | BX15: 2144142 | BY15: 7856469 | BZ15: 1080732 | CA15: 1368334 | CB15: 13198 | CC15: 19046 | CF15: 221512 | CG15: 299926 | CH15: 6128229 | CI15: 1569164 | CJ15: 15729422 | CK15: 8866295 | CN15: 228814 | CO15: 30281 | CP15: 14103868 | CQ15: 8500722 | CR15: 1396740 | CS15: 335292 | CT15: 999850 | CU15: 157711 | CV15: 1761 | CW15: 1982 | CX15: 58421287 | CY15: 38016650 | CZ15: 79041268 | DA15: 62461541 | DB15: 8452563 | DC15: 8452563 | DD15: 13982173 | DE15: 13982173 | DF15: 12030422 | DG15: 12802057 | DJ15: 25325241 | DK15: 14115899 | DP15: 59790399 | DQ15: 49352692 | DR15: 44405 | DT15: 44405 | DV15: 44405 | EP15: 19206464 | EQ15: 13108849 | ER15: 3828865 | ES15: 3107284 | EV15: 752773 | EW15: 853490 | FH15: 187196 | FI15: 41121 | FJ15: 361790 | FK15: 365795 | FN15: 527815 | FO15: 265522 | FP15: 906155 | FQ15: 894890 | FR15: 980676 | FS15: 610078 | FT15: 15377599 | FU15: 10001565 | FZ15: 112460 | GA15: 76388 | GB15: 19250869 | GC15: 13108849 | GD15: 79041268 | GE15: 62461541
A16: 20006 | B16: 0 | C16: 200466854 | D16: "YANGIYO'L YOG'-MOY" AJ | E16: 27 | F16: 22 | G16: 0 | H16: 8 | I16: 2019 | J16: 4 | K16: N | L16: 2 | M16: 30 | N16: 0 | O16: 43997.685 | P16: 42338370 | Q16: 43742333 | R16: 25924747 | S16: 26813671 | T16: 16413623 | U16: 16928662 | W16: 74882 | AA16: 74882 | AB16: 1551476 | AC16: 1551476 | AD16: 536 | AE16: 536 | AL16: 1550940 | AM16: 1550940 | AN16: 90032 | AO16: 1586341 | AP16: 39370 | AQ16: 77451 | AR16: 272151 | AS16: 401169 | AV16: 18366652 | AW16: 20619981 | AX16: 23253138 | AY16: 30951383 | AZ16: 15902901 | BA16: 7811552 | BB16: 218545 | BC16: 77080 | BD16: 7131692 | BE16: 23062751 | BH16: 88373 | BI16: 388499 | BL16: 12413149 | BM16: 10350372 | BP16: 159385 | BQ16: 762559 | BX16: 9076440 | BY16: 2144142 | BZ16: 448085 | CA16: 1080732 | CB16: 14446 | CC16: 13198 | CF16: 86982 | CG16: 221512 | CH16: 2627811 | CI16: 6128229 | CJ16: 16264021 | CK16: 15729422 | CN16: 1088384 | CO16: 228814 | CP16: 15161537 | CQ16: 14103868 | CR16: 14100 | CS16: 1396740 | CT16: 820944 | CU16: 999850 | CV16: 1761 | CW16: 1761 | CX16: 52841386 | CY16: 58421287 | CZ16: 71208038 | DA16: 79041268 | DB16: 8452563 | DC16: 8452563 | DD16: 13982173 | DE16: 13982173 | DF16: 12289497 | DG16: 12030422 | DJ16: 24391431 | DK16: 25325241 | DP16: 59115664 | DQ16: 59790399 | DR16: 606406 | DS16: 44405 | DT16: 606406 | DU16: 44405 | DV16: 606406 | DW16: 44405 | EP16: 11485968 | EQ16: 19206464 | ER16: 7485968 | ES16: 3828865 | EV16: 1377308 | EW16: 752773 | FH16: 147615 | FI16: 187196 | FJ16: 2339696 | FK16: 361790 | FN16: 1334535 | FO16: 527815 | FP16: 244538 | FQ16: 906155 | FR16: 1562310 | FS16: 980676 | FT16: 4000000 | FU16: 15377599 | FZ16: 479966 | GA16: 112460 | GB16: 12092374 | GC16: 19250869 | GD16: 71208038 | GE16: 79041268
A17: 20006 | B17: 0 | C17: 200466854 | D17: "YANGIYO'L YOG'-MOY" AJ | E17: 27 | F17: 22 | G17: 0 | H17: 8 | I17: 2018 | J17: 4 | K17: N | L17: 1 | M17: 30 | N17: 0 | O17: 43544.547 | P17: 38932932 | Q17: 39502704 | R17: 23923877 | S17: 24901822 | T17: 15009055 | U17: 14600882 | W17: 926625 | AA17: 926625 | AB17: 1585976 | AC17: 1551476 | AD17: 536 | AE17: 536 | AL17: 1585440 | AM17: 1550940 | AN17: 86875 | AO17: 90032 | AP17: 31000 | AQ17: 39370 | AR17: 303658 | AS17: 272151 | AV17: 17016564 | AW17: 17480536 | AX17: 16452963 | AY17: 23253138 | AZ17: 11836039 | BA17: 15902901 | BC17: 218545 | BD17: 4616924 | BE17: 7131692 | BH17: 9788 | BI17: 88373 | BL17: 7348754 | BM17: 12413149 | BP17: 1151498 | BQ17: 159385 | BX17: 1408778 | BY17: 9076440 | BZ17: 921978 | CA17: 448085 | CC17: 14446 | CF17: 8692 | CG17: 86982 | CH17: 3857808 | CI17: 2627811 | CJ17: 15248287 | CK17: 16264021 | CN17: 783436 | CO17: 1088384 | CP17: 14454614 | CQ17: 15161537 | CR17: 10237 | CS17: 14100 | CT17: 944 | CU17: 820944 | CV17: 1761 | CW17: 1761 | CX17: 39062497 | CY17: 52841386 | CZ17: 56079061 | DA17: 70321922 | DB17: 8452563 | DC17: 8452563 | DD17: 13982173 | DE17: 13982173 | DF17: 11890634 | DG17: 11403381 | DJ17: 18841837 | DK17: 24391431 | DP17: 53167207 | DQ17: 58229548 | DS17: 606406 | DU17: 606406 | DW17: 606406 | EP17: 2911854 | EQ17: 11485968 | ER17: 2905854 | ES17: 7485968 | EV17: 352496 | EW17: 1377308 | FH17: 178572 | FI17: 147615 | FJ17: 911150 | FK17: 2339696 | FN17: 264278 | FO17: 1334535 | FP17: 210021 | FQ17: 244538 | FR17: 700720 | FS17: 1562310 | FU17: 4000000 | FV17: 6000 | FZ17: 288617 | GA17: 479966 | GB17: 2911854 | GC17: 12092374 | GD17: 56079061 | GE17: 70321922
A18: 20006 | B18: 0 | C18: 200670095 | D18: "QARSHI YOG'-EKSTRAKSIYA" AJ | E18: 10 | F18: 1 | G18: 0 | H18: 1 | I18: 2021 | J18: 4 | K18: N | L18: 2 | M18: 30 | N18: 0 | O18: 44621.453 | P18: 38755239 | Q18: 41486818 | R18: 17301764 | S18: 19150112 | T18: 21453475 | U18: 22336706 | AB18: 509341 | AC18: 509341 | AD18: 215004 | AE18: 215004 | AJ18: 11942 | AK18: 11942 | AL18: 282395 | AM18: 282395 | AN18: 588673 | AO18: 1982818 | AP18: 10383 | AQ18: 10383 | AR18: 373730 | AS18: 299376 | AV18: 22935602 | AW18: 25138624 | AX18: 35357080 | AY18: 49329800 | AZ18: 8849286 | BA18: 29709719 | BD18: 26507794 | BE18: 19620081 | BI18: 3489625 | BL18: 8448636 | BM18: 33056011 | BN18: 1522422 | BO18: 10772721 | BP18: 548462 | BQ18: 306115 | BV18: 30446 | BW18: 22434 | BX18: 6404756 | BY18: 23976058 | BZ18: 1331998 | CA18: 8588531 | CB18: 114557 | CC18: 75832 | CH18: 18417 | CI18: 87041 | CJ18: 677 | CK18: 603476 | CL18: 427 | CM18: 603476 | CR18: 250 | CT18: 26283 | CU18: 26283 | CW18: 12151188 | CX18: 43832676 | CY18: 98656383 | CZ18: 66768278 | DA18: 123795007 | DB18: 4772647 | DC18: 4772647 | DD18: 2707888 | DE18: 2707888 | DF18: 11998348 | DG18: 11985120 | DJ18: -3992054 | DK18: -13835557 | DL18: 2437191 | DM18: 28055601 | DP18: 17924020 | DQ18: 33685699 | DR18: 1016863 | DS18: 1016863 | EL18: 1016863 | EM18: 1016863 | EP18: 47827395 | EQ18: 89092445 | ER18: 28087395 | ES18: 31097565 | ET18: 602683 | EU18: 23677476 | EV18: 25277643 | EW18: 28095664 | EZ18: 434742 | FA18: 426833 | FH18: 200297 | FI18: 294354 | FJ18: 66697 | FK18: 92505 | FM18: 2085 | FN18: 3627 | FP18: 1233472 | FQ18: 666715 | FR18: 763362 | FS18: 1408714 | FT18: 17000000 | FU18: 57994880 | FV18: 2740000 | FZ18: 107555 | GA18: 110695 | GB18: 48844258 | GC18: 90109308 | GD18: 66768278 | GE18: 123795007
A19: 20006 | B19: 0 | C19: 200670095 | D19: "QARSHI YOG'-EKSTRAKSIYA" AJ | E19: 10 | F19: 1 | G19: 0 | H19: 1 | I19: 2020 | J19: 4 | K19: N | L19: 2 | M19: 30 | N19: 0 | O19: 44257.576 | P19: 36554370 | Q19: 38755239 | R19: 15120747 | S19: 17301764 | T19: 21433623 | U19: 21453475 | AB19: 509341 | AC19: 509341 | AD19: 215004 | AE19: 215004 | AJ19: 11942 | AK19: 11942 | AL19: 282395 | AM19: 282395 | AN19: 302740 | AO19: 588673 | AP19: 10383 | AQ19: 10383 | AR19: 523647 | AS19: 373730 | AV19: 22779734 | AW19: 22935602 | AX19: 28200670 | AY19: 35357080 | AZ19: 4456301 | BA19: 8849286 | BD19: 23744369 | BE19: 26507794 | BL19: 7568598 | BM19: 8448636 | BN19: 5195141 | BO19: 1522422 | BP19: 1282780 | BQ19: 548462 | BT19: 6666 | BV19: 12874 | BW19: 30446 | BX19: 6224967 | BY19: 6404756 | BZ19: 32126 | CA19: 1331998 | CC19: 114557 | CH19: 9185 | CI19: 18417 | CJ19: 934254 | CK19: 677 | CN19: 905574 | CO19: 427 | CP19: 28680 | CS19: 250 | CT19: 26283 | CU19: 26283 | CX19: 36729805 | CY19: 43832676 | CZ19: 59509539 | DA19: 66768278 | DB19: 4772647 | DC19: 4772647 | DD19: 2707888 | DE19: 2707888 | DF19: 10342534 | DG19: 11998348 | DJ19: -4039924 | DK19: -3992054 | DM19: 2437191 | DP19: 13783145 | DQ19: 17924020 | DR19: 422493 | DS19: 1016863 | EL19: 422493 | EM19: 1016863 | EP19: 45303931 | EQ19: 47827395 | ER19: 32079402 | ES19: 28087395 | ET19: 2933741 | EU19: 602683 | EV19: 28229203 | EW19: 25277643 | EZ19: 434742 | FA19: 434742 | FH19: 314663 | FI19: 200297 | FJ19: 51700 | FK19: 66697 | FN19: 122904 | FO19: 3627 | FP19: 1732589 | FQ19: 1233472 | FR19: 1123636 | FS19: 763362 | FT19: 13224529 | FU19: 17000000 | FW19: 2740000 | FZ19: 69965 | GA19: 107555 | GB19: 45726424 | GC19: 48844258 | GD19: 59509569 | GE19: 66768278
A20: 20006 | B20: 0 | C20: 200670095 | D20: "QARSHI YOG'-EKSTRAKSIYA" AJ | E20: 10 | F20: 1 | G20: 0 | H20: 1 | I20: 2019 | J20: 4 | K20: N | L20: 1 | M20: 30 | N20: 0 | O20: 43882.724 | P20: 32192851 | Q20: 36554370 | R20: 13377959 | S20: 15120747 | T20: 18814892 | U20: 21433623 | AB20: 732341 | AC20: 509341 | AD20: 215004 | AE20: 215004 | AJ20: 11942 | AK20: 11942 | AL20: 505395 | AM20: 282395 | AN20: 497788 | AO20: 302740 | AP20: 10383 | AQ20: 10383 | AR20: 555408 | AS20: 523647 | AV20: 20610812 | AW20: 22779734 | AX20: 25075365 | AY20: 28200670 | AZ20: 9446085 | BA20: 4456301 | BD20: 15629280 | BE20: 23744369 | BL20: 9836674 | BM20: 7568598 | BN20: 843875 | BO20: 5195141 | BP20: 242076 | BQ20: 1282780 | BT20: 51188 | BU20: 6666 | BV20: 47463 | BW20: 12874 | BX20: 8221968 | BY20: 6224967 | BZ20: 1262466 | CA20: 32126 | CH20: 11513 | CI20: 9185 | CJ20: 4340687 | CK20: 934254 | CN20: 572 | CO20: 905574 | CP20: 4335013 | CQ20: 28680 | CR20: 5102 | CT20: 26283 | CU20: 26283 | CX20: 39279009 | CY20: 36729805 | CZ20: 59889821 | DA20: 59509539 | DB20: 4772647 | DC20: 4772647 | DD20: 2707888 | DE20: 2707888 | DF20: 10247646 | DG20: 10342534 | DJ20: 6390216 | DK20: -4039924 | DP20: 24118397 | DQ20: 13783145 | DR20: 2878900 | DS20: 422493 | EJ20: 1900000 | EL20: 978900 | EM20: 422493 | EP20: 32892524 | EQ20: 45303901 | ER20: 9868252 | ES20: 32079372 | EU20: 2933741 | EV20: 6140150 | EW20: 28229203 | EZ20: 593217 | FA20: 434742 | FH20: 999805 | FI20: 314633 | FJ20: 426748 | FK20: 51700 | FL20: 47734 | FN20: 499023 | FO20: 122904 | FP20: 727605 | FQ20: 1732589 | FR20: 398054 | FS20: 1123636 | FT20: 23024272 | FU20: 13224529 | FZ20: 35916 | GA20: 69965 | GB20: 35771424 | GC20: 45726394 | GD20: 59889821 | GE20: 59509539
A21: 20006 | B21: 0 | C21: 200670095 | D21: "QARSHI YOG'-EKSTRAKSIYA" AJ | E21: 10 | F21: 1 | G21: 0 | H21: 1 | I21: 2018 | J21: 4 | K21: N | L21: 1 | M21: 30 | N21: 0 | O21: 43511.626 | P21: 29022058 | Q21: 30225010 | R21: 12024197 | S21: 12821659 | T21: 16997861 | U21: 17403351 | AB21: 766841 | AC21: 732341 | AD21: 215004 | AE21: 215004 | AJ21: 11942 | AK21: 11942 | AL21: 539895 | AM21: 505395 | AN21: 513260 | AO21: 497788 | AP21: 10383 | AQ21: 10383 | AR21: 578029 | AS21: 555408 | AV21: 18866374 | AW21: 19199271 | AX21: 10412913 | AY21: 25075365 | AZ21: 6725532 | BA21: 9446085 | BD21: 3687381 | BE21: 15629280 | BL21: 4364393 | BM21: 9836674 | BN21: 347597 | BO21: 843875 | BP21: 236062 | BQ21: 242076 | BT21: 1245671 | BU21: 51188 | BV21: 68023 | BW21: 47463 | BX21: 2517022 | BY21: 8221968 | BZ21: 265298 | CA21: 1262466 | CH21: 32317 | CI21: 11513 | CJ21: 7274295 | CK21: 4340687 | CN21: 13007 | CO21: 572 | CP21: 7248247 | CQ21: 4335013 | CR21: 13041 | CS21: 5102 | CT21: 26283 | CU21: 26283 | CX21: 22077884 | CY21: 39279009 | CZ21: 40944258 | DA21: 58478280 | DB21: 4772647 | DC21: 4772647 | DD21: 2707888 | DE21: 2707888 | DF21: 8704826 | DG21: 8836105 | DJ21: 5972767 | DK21: 6390216 | DP21: 22158128 | DQ21: 22706856 | DR21: 1117220 | DS21: 2878900 | EJ21: 649773 | EK21: 1900000 | EL21: 467447 | EM21: 978900 | EP21: 17668910 | EQ21: 32892524 | ER21: 8978910 | ES21: 9868252 | EV21: 2004504 | EW21: 6140150 | EZ21: 1235305 | FA21: 593217 | FH21: 53719 | FI21: 999805 | FJ21: 3319504 | FK21: 426748 | FL21: 39918 | FM21: 47734 | FN21: 867171 | FO21: 499023 | FP21: 1111142 | FQ21: 727605 | FR21: 330691 | FS21: 398054 | FU21: 23024272 | FX21: 8690000 | FZ21: 16956 | GA21: 35916 | GB21: 18786130 | GC21: 35771424 | GD21: 40944258 | GE21: 58478280
A22: 20006 | B22: 0 | C22: 200930049 | D22: YOG`GAR AJ | E22: 35 | F22: 9 | G22: 0 | H22: 1 | I22: 2021 | J22: 4 | K22: N | L22: 2 | M22: 30 | N22: 0 | O22: 44664.438 | P22: 10176690 | Q22: 10203817 | R22: 7071583 | S22: 7379656 | T22: 3105107 | U22: 2824161 | V22: 15049 | W22: 15049 | X22: 2947 | Y22: 3699 | Z22: 12102 | AA22: 11350 | AB22: 151215 | AC22: 151215 | AD22: 1215 | AE22: 1215 | AF22: 150000 | AG22: 150000 | AP22: 426716 | AQ22: 512888 | AR22: 163020 | AS22: 110789 | AV22: 3858160 | AW22: 3610403 | AX22: 6429817 | AY22: 6485315 | AZ22: 4093609 | BA22: 1822448 | BC22: 1859681 | BD22: 2336208 | BE22: 2803186 | BL22: 4839014 | BM22: 3465451 | BP22: 1724868 | BQ22: 918473 | BV22: 237404 | BW22: 7333 | BX22: 75408 | BY22: 1699394 | BZ22: 2753537 | CA22: 449530 | CB22: 47797 | CC22: 45412 | CI22: 345309 | CJ22: 16037 | CK22: 4716 | CN22: 8295 | CO22: 1967 | CQ22: 2749 | CR22: 7742 | CX22: 11284868 | CY22: 9955482 | CZ22: 15143028 | DA22: 13565885 | DB22: 4093375 | DC22: 4093375 | DF22: 3153869 | DG22: 1677036 | DJ22: 1962589 | DK22: 45347 | DN22: 3716069 | DP22: 12925902 | DQ22: 5815758 | EP22: 2217126 | EQ22: 7750127 | ER22: 2017126 | ES22: 7368309 | EV22: 1033119 | EW22: 1096467 | FI22: 5079908 | FJ22: 364245 | FK22: 295255 | FN22: 351185 | FO22: 1828 | FQ22: 171263 | FR22: 192300 | FS22: 487764 | FU22: 181818 | FV22: 200000 | FW22: 200000 | FZ22: 76277 | GA22: 235824 | GB22: 2217126 | GC22: 7750127 | GD22: 15143028 | GE22: 13565885
A23: 60131 | B23: 0 | C23: 200930049 | D23: YOG`GAR AJ | E23: 35 | F23: 9 | G23: 0 | H23: 1 | I23: 2020 | J23: 4 | K23: N | L23: 1 | M23: 30 | N23: 0 | O23: 44209.598 | P23: 10176690 | Q23: 10176690 | R23: 6980732 | S23: 7071583 | T23: 3195958 | U23: 3105107 | V23: 15049 | W23: 15049 | X23: 2759 | Y23: 2947 | Z23: 12290 | AA23: 12102 | AB23: 151251 | AC23: 151251 | AD23: 1251 | AE23: 1251 | AF23: 150000 | AG23: 150000 | AH23: 0 | AJ23: 0 | AL23: 0 | AN23: 0 | AP23: 426716 | AQ23: 426716 | AR23: 202465 | AS23: 163020 | AT23: 0 | AV23: 3988680 | AW23: 3858196 | AX23: 8492107 | AY23: 6429817 | AZ23: 5620014 | BA23: 4093609 | BB23: 0 | BD23: 2872093 | BE23: 2336208 | BF23: 0 | BH23: 0 | BJ23: 0 | BL23: 4772154 | BM23: 4839014 | BN23: 0 | BP23: 1770515 | BQ23: 1724868 | BR23: 0 | BT23: 0 | BV23: 107453 | BW23: 237404 | BX23: 434648 | BY23: 75408 | BZ23: 2322931 | CA23: 2753537 | CB23: 47797 | CC23: 47797 | CD23: 0 | CF23: 0 | CH23: 88810 | CJ23: 0 | CK23: 16037 | CL23: 0 | CN23: 0 | CO23: 8295 | CP23: 0 | CR23: 0 | CS23: 7742 | CT23: 0 | CV23: 0 | CX23: 13264261 | CY23: 11284868 | CZ23: 17252941 | DA23: 15143064 | DB23: 4093375 | DC23: 4093375 | DD23: 0 | DF23: 3153869 | DG23: 3153869 | DH23: 0 | DJ23: 543536 | DK23: 1962589 | DL23: 0 | DN23: 3716069 | DO23: 3716069 | DP23: 11506849 | DQ23: 12925902 | DR23: 0 | DT23: 0 | DV23: 0 | DX23: 0 | DZ23: 0 | EB23: 0 | ED23: 0 | EF23: 0 | EH23: 0 | EJ23: 0 | EL23: 0 | EN23: 0 | EP23: 5746092 | EQ23: 2217162 | ER23: 3008273 | ES23: 2017162 | ET23: 0 | EV23: 1512139 | EW23: 1033119 | EX23: 0 | EZ23: 0 | FB23: 0 | FD23: 0 | FF23: 0 | FH23: 3399 | FJ23: 125748 | FK23: 364245 | FL23: 0 | FN23: 340266 | FO23: 351185 | FP23: 754883 | FR23: 215918 | FS23: 192336 | FT23: 2477819 | FV23: 260000 | FW23: 200000 | FX23: 0 | FZ23: 55920 | GA23: 76277 | GB23: 5746092 | GC23: 2217162 | GD23: 17252941 | GE23: 15143064
A24: 20006 | B24: 0 | C24: 200930049 | D24: YOG`GAR AJ | E24: 35 | F24: 9 | G24: 0 | H24: 1 | I24: 2019 | J24: 4 | K24: N | L24: 1 | M24: 30 | N24: 0 | O24: 43879.874 | P24: 9322105 | Q24: 9597307 | R24: 6084929 | S24: 6368075 | T24: 3237176 | U24: 3229232 | V24: 15049 | W24: 15049 | X24: 1442 | Y24: 2195 | Z24: 13607 | AA24: 12854 | AB24: 151215 | AC24: 151215 | AD24: 1215 | AE24: 1215 | AF24: 150000 | AG24: 150000 | AN24: 124020 | AQ24: 422075 | AR24: 211375 | AS24: 256572 | AV24: 3737393 | AW24: 4071948 | AX24: 19942373 | AY24: 11712756 | AZ24: 14420867 | BA24: 3996582 | BD24: 5521506 | BE24: 7716174 | BL24: 3307895 | BM24: 6567410 | BP24: 321710 | BQ24: 1497591 | BV24: 196837 | BW24: 125764 | BX24: 1642965 | BY24: 2025246 | BZ24: 1056353 | CA24: 2739864 | CB24: 47797 | CC24: 47797 | CH24: 42233 | CI24: 131148 | CJ24: 113826 | CK24: 216640 | CN24: 6746 | CO24: 49362 | CP24: 49469 | CR24: 57611 | CS24: 167278 | CX24: 23364094 | CY24: 18496806 | CZ24: 27101487 | DA24: 22568754 | DB24: 4093375 | DC24: 4093375 | DF24: 1241684 | DG24: 2797795 | DJ24: 2820741 | DK24: 2898705 | DN24: 3716592 | DO24: 3716592 | DP24: 11872392 | DQ24: 13506467 | EP24: 15229095 | EQ24: 9062287 | ER24: 8072645 | ES24: 3136211 | EV24: 6022404 | EW24: 1075220 | FH24: 45510 | FJ24: 779058 | FK24: 1531723 | FN24: 839105 | FO24: 169225 | FP24: 1455 | FQ24: 42607 | FR24: 366892 | FS24: 205885 | FT24: 6906450 | FU24: 5045576 | FV24: 250000 | FW24: 880500 | FZ24: 18221 | GA24: 111551 | GB24: 15229095 | GC24: 9062287 | GD24: 27101487 | GE24: 22568754
A25: 20006 | B25: 0 | C25: 200930049 | D25: YOG`GAR AJ | E25: 35 | F25: 9 | G25: 0 | H25: 1 | I25: 2018 | J25: 4 | K25: N | L25: 2 | M25: 30 | N25: 0 | O25: 43537.405 | P25: 9213443 | Q25: 9322105 | R25: 5739706 | S25: 6084929 | T25: 3473737 | U25: 3237176 | V25: 15049 | W25: 15049 | X25: 1254 | Y25: 1442 | Z25: 13795 | AA25: 13607 | AB25: 185715 | AC25: 151215 | AD25: 1215 | AE25: 1215 | AF25: 184500 | AG25: 150000 | AN25: 124020 | AO25: 124020 | AR25: 170650 | AS25: 211375 | AV25: 3967917 | AW25: 3737393 | AX25: 4107960 | AY25: 19942373 | AZ25: 2979906 | BA25: 14420867 | BD25: 1128054 | BE25: 5521506 | BL25: 4208839 | BM25: 3307895 | BQ25: 321710 | BV25: 122912 | BW25: 196837 | BX25: 3735230 | BY25: 1642965 | BZ25: 247058 | CA25: 1056353 | CB25: 58322 | CC25: 47797 | CH25: 45317 | CI25: 42233 | CJ25: 143786 | CK25: 113826 | CN25: 143786 | CO25: 6746 | CQ25: 49469 | CS25: 57611 | CX25: 8460585 | CY25: 23364094 | CZ25: 12428502 | DA25: 27101487 | DB25: 4093375 | DC25: 4093375 | DF25: 1419885 | DG25: 1241684 | DJ25: 1826964 | DK25: 2820741 | DO25: 3716592 | DP25: 7340224 | DQ25: 11872392 | EP25: 5088278 | EQ25: 15229095 | ER25: 2115450 | ES25: 8072645 | EV25: 649182 | EW25: 6022404 | FH25: 112163 | FI25: 45510 | FJ25: 805858 | FK25: 779058 | FN25: 303968 | FO25: 839105 | FP25: 5827 | FQ25: 1455 | FR25: 147966 | FS25: 366892 | FT25: 2722828 | FU25: 6906450 | FV25: 250000 | FW25: 250000 | FZ25: 90486 | GA25: 18221 | GB25: 5088278 | GC25: 15229095 | GD25: 12428502 | GE25: 27101487
A26: 20006 | B26: 0 | C26: 200595877 | D26: "YEROSTIGAZ" AJ | E26: 27 | F26: 16 | G26: 0 | H26: 1 | I26: 2021 | J26: 4 | K26: N | L26: 2 | M26: 30 | N26: 0 | O26: 44619.886 | P26: 7161829 | Q26: 7163161 | R26: 3979643 | S26: 4386868 | T26: 3182186 | U26: 2776293 | V26: 1949 | W26: 1949 | X26: 891 | Y26: 1200 | Z26: 1058 | AA26: 749 | AB26: 20437 | AC26: 20437 | AD26: 205 | AE26: 205 | AH26: 20232 | AI26: 20232 | AV26: 3203681 | AW26: 2797479 | AX26: 1753197 | AY26: 1459124 | AZ26: 1753197 | BA26: 1459124 | BH26: 149357 | BI26: 143389 | BL26: 5941938 | BM26: 10302419 | BP26: 5789622 | BQ26: 7008656 | BX26: 58786 | BY26: 3189567 | BZ26: 15433 | CA26: 20609 | CB26: 434 | CC26: 1379 | CH26: 77663 | CI26: 82208 | CJ26: 1216812 | CK26: 5330 | CN26: 1214484 | CO26: 5318 | CR26: 2328 | CS26: 12 | CV26: 12330 | CW26: 12330 | CX26: 9073634 | CY26: 11922592 | CZ26: 12277315 | DA26: 14720071 | DB26: 677310 | DC26: 677310 | DD26: 601753 | DE26: 601753 | DF26: 5049241 | DG26: 5049241 | DJ26: 5150926 | DK26: 7081657 | DP26: 11479230 | DQ26: 13409961 | EP26: 798085 | EQ26: 1310110 | ER26: 798085 | ES26: 1281711 | EV26: 1407 | EW26: 209123 | FI26: 3863 | FJ26: 326445 | FK26: 353265 | FO26: 2 | FP26: 84563 | FQ26: 4640 | FR26: 369298 | FS26: 685363 | FW26: 28399 | FZ26: 16372 | GA26: 25455 | GB26: 798085 | GC26: 1310110 | GD26: 12277315 | GE26: 14720071
A27: 20006 | B27: 0 | C27: 200595877 | D27: "YEROSTIGAZ" AJ | E27: 27 | F27: 16 | G27: 0 | H27: 1 | I27: 2020 | J27: 4 | K27: N | L27: 1 | M27: 30 | N27: 0 | O27: 44242.694 | P27: 6994308.8 | Q27: 7161828.6 | R27: 3560122.5 | S27: 3979642.7 | T27: 3434186.4 | U27: 3182185.9 | V27: 1948.56 | W27: 1948.56 | X27: 581.85 | Y27: 890.53 | Z27: 1366.71 | AA27: 1058.03 | AB27: 205.33 | AC27: 20436.85 | AD27: 205.33 | AE27: 205.33 | AF27: 0 | AG27: 0 | AH27: 0 | AI27: 20231.52 | AJ27: 0 | AK27: 0 | AL27: 0 | AM27: 0 | AN27: 0 | AO27: 0 | AP27: 0 | AQ27: 0 | AR27: 0 | AS27: 0 | AT27: 0 | AU27: 0 | AV27: 3435758.4 | AW27: 3203680.8 | AX27: 1862462.7 | AY27: 1753196.7 | AZ27: 1862462.7 | BA27: 1753196.7 | BB27: 0 | BC27: 0 | BD27: 0 | BE27: 0 | BF27: 0 | BG27: 0 | BH27: 5002.61 | BI27: 149357.09 | BJ27: 0 | BK27: 0 | BL27: 1793026.9 | BM27: 5941937.6 | BN27: 0 | BO27: 0 | BP27: 689173.49 | BQ27: 5789621.6 | BR27: 0 | BS27: 0 | BT27: 0 | BU27: 0 | BV27: 0 | BW27: 0 | BX27: 997079.53 | BY27: 58785.69 | BZ27: 6000.23 | CA27: 15433.17 | CB27: 1933.9 | CC27: 434.1 | CD27: 0 | CE27: 0 | CF27: 0 | CG27: 0 | CH27: 98839.7 | CI27: 77663.03 | CJ27: 108439.44 | CK27: 1216812.5 | CL27: 0 | CM27: 0 | CN27: 107106.14 | CO27: 1214484.5 | CP27: 0 | CQ27: 0 | CR27: 1333.3 | CS27: 2328.02 | CT27: 0 | CU27: 0 | CV27: 12330.13 | CW27: 12330.13 | CX27: 3781261.8 | CY27: 9073634 | CZ27: 7217020.2 | DA27: 12277315 | DB27: 677310 | DC27: 677310 | DD27: 601753.05 | DE27: 601753.05 | DF27: 4842600.4 | DG27: 5049241.3 | DH27: 0 | DI27: 0 | DJ27: 398402.65 | DK27: 5150925.9 | DL27: 0 | DM27: 0 | DN27: 0 | DO27: 0 | DP27: 6520066.1 | DQ27: 11479230 | DR27: 0 | DS27: 0 | DT27: 0 | DU27: 0 | DV27: 0 | DW27: 0 | DX27: 0 | DY27: 0 | DZ27: 0 | EA27: 0 | EB27: 0 | EC27: 0 | ED27: 0 | EE27: 0 | EF27: 0 | EG27: 0 | EH27: 0 | EI27: 0 | EJ27: 0 | EK27: 0 | EL27: 0 | EM27: 0 | EN27: 0 | EO27: 0 | EP27: 696954.05 | EQ27: 798084.58 | ER27: 696954.05 | ES27: 798084.58 | ET27: 0 | EU27: 0 | EV27: 8673.84 | EW27: 1407.06 | EX27: 0 | EY27: 0 | EZ27: 0 | FA27: 0 | FB27: 0 | FC27: 0 | FD27: 0 | FE27: 0 | FF27: 0 | FG27: 0 | FH27: 0 | FI27: 0 | FJ27: 383718.41 | FK27: 326445.24 | FL27: 0 | FM27: 0 | FN27: 34198.19 | FO27: 0 | FP27: 0 | FQ27: 84563.23 | FR27: 244663.57 | FS27: 369296.67 | FT27: 0 | FU27: 0 | FV27: 0 | FW27: 0 | FX27: 0 | FY27: 0 | FZ27: 25700.04 | GA27: 16372.38 | GB27: 696954.05 | GC27: 798084.58 | GD27: 7217020.2 | GE27: 12277315
A28: 20006 | B28: 0 | C28: 200595877 | D28: "YEROSTIGAZ" AJ | E28: 27 | F28: 16 | G28: 0 | H28: 1 | I28: 2019 | J28: 4 | K28: N | L28: 1 | M28: 30 | N28: 0 | O28: 43876.893 | P28: 6566119 | Q28: 6565983.8 | R28: 3117837.5 | S28: 3368444.2 | T28: 3448281.4 | U28: 3197539.6 | V28: 1948.56 | W28: 1948.56 | X28: 273.16 | Y28: 581.85 | Z28: 1675.4 | AA28: 1366.71 | AB28: 205.33 | AC28: 205.33 | AD28: 205.33 | AE28: 205.33 | AF28: 0 | AG28: 0 | AH28: 0 | AI28: 0 | AJ28: 0 | AK28: 0 | AL28: 0 | AM28: 0 | AN28: 0 | AO28: 0 | AP28: 0 | AQ28: 0 | AR28: 0 | AS28: 0 | AT28: 0 | AU28: 0 | AV28: 3450162.1 | AW28: 3199111.6 | AX28: 2042345.2 | AY28: 1862462.7 | AZ28: 2042345.2 | BA28: 1862462.7 | BB28: 0 | BC28: 0 | BD28: 0 | BE28: 0 | BF28: 0 | BG28: 0 | BH28: 118759.5 | BI28: 5002.61 | BJ28: 0 | BK28: 0 | BL28: 608726.32 | BM28: 1793026.9 | BN28: 0 | BO28: 0 | BP28: 54164.39 | BQ28: 689173.49 | BR28: 0 | BS28: 0 | BT28: 0 | BU28: 0 | BV28: 0 | BW28: 0 | BX28: 499684.08 | BY28: 997079.53 | BZ28: 0 | CA28: 6000.23 | CB28: 0.47 | CC28: 1933.9 | CD28: 0 | CE28: 0 | CF28: 0 | CG28: 0 | CH28: 54877.38 | CI28: 98839.7 | CJ28: 1.32 | CK28: 108439.44 | CL28: 0 | CM28: 0 | CN28: 0 | CO28: 107106.14 | CP28: 0 | CQ28: 0 | CR28: 1.32 | CS28: 1333.3 | CT28: 0 | CU28: 0 | CV28: 12330.13 | CW28: 12330.13 | CX28: 2782162.5 | CY28: 3781261.8 | CZ28: 6232324.7 | DA28: 6980373.4 | DB28: 677310 | DC28: 677310 | DD28: 601753.05 | DE28: 601753.05 | DF28: 4574681.8 | DG28: 4605953.6 | DH28: 0 | DI28: 0 | DJ28: -3155119.3 | DK28: 398402.65 | DL28: 0 | DM28: 0 | DN28: 0 | DO28: 0 | DP28: 2698625.5 | DQ28: 6283419.3 | DR28: 0 | DS28: 0 | DT28: 0 | DU28: 0 | DV28: 0 | DW28: 0 | DX28: 0 | DY28: 0 | DZ28: 0 | EA28: 0 | EB28: 0 | EC28: 0 | ED28: 0 | EE28: 0 | EF28: 0 | EG28: 0 | EH28: 0 | EI28: 0 | EJ28: 0 | EK28: 0 | EL28: 0 | EM28: 0 | EN28: 0 | EO28: 0 | EP28: 3533699.1 | EQ28: 696954.05 | ER28: 3531971.1 | ES28: 696954.05 | ET28: 0 | EU28: 0 | EV28: 908460.4 | EW28: 8673.84 | EX28: 0 | EY28: 0 | EZ28: 0 | FA28: 0 | FB28: 0 | FC28: 0 | FD28: 0 | FE28: 0 | FF28: 0 | FG28: 0 | FH28: 1717.07 | FI28: 0 | FJ28: 1056823.3 | FK28: 383718.41 | FL28: 0 | FM28: 0 | FN28: 595957.14 | FO28: 34198.19 | FP28: 0 | FQ28: 0 | FR28: 913961.13 | FS28: 244663.57 | FT28: 0 | FU28: 0 | FV28: 1728 | FW28: 0 | FX28: 0 | FY28: 0 | FZ28: 55052.09 | GA28: 25700.04 | GB28: 3533699.1 | GC28: 696954.05 | GD28: 6232324.7 | GE28: 6980373.4
A29: 20006 | B29: 0 | C29: 200595877 | D29: "YEROSTIGAZ" AJ | E29: 27 | F29: 16 | G29: 0 | H29: 1 | I29: 2018 | J29: 4 | K29: N | L29: 1 | M29: 30 | N29: 0 | O29: 43507.829 | P29: 6291881 | Q29: 6291764 | R29: 2759272 | S29: 3006686 | T29: 3532609 | U29: 3285078 | V29: 1375 | W29: 1949 | X29: 242 | Y29: 273 | Z29: 1133 | AA29: 1676 | AB29: 205 | AC29: 205 | AD29: 205 | AE29: 205 | AF29: 0 | AG29: 0 | AH29: 0 | AI29: 0 | AJ29: 0 | AK29: 0 | AL29: 0 | AM29: 0 | AN29: 0 | AO29: 0 | AP29: 0 | AQ29: 0 | AR29: 0 | AS29: 0 | AT29: 0 | AU29: 0 | AV29: 3533947 | AW29: 3286959 | AX29: 2092362 | AY29: 2042345 | AZ29: 2092362 | BA29: 2042345 | BB29: 0 | BC29: 0 | BD29: 0 | BE29: 0 | BF29: 0 | BG29: 0 | BH29: 54369 | BI29: 118760 | BJ29: 0 | BK29: 0 | BL29: 39785 | BM29: 608726 | BN29: 0 | BO29: 0 | BP29: 4865 | BQ29: 54164 | BR29: 0 | BS29: 0 | BT29: 0 | BU29: 0 | BV29: 20 | BW29: 0 | BX29: 17355 | BY29: 499684 | BZ29: 13222 | CA29: 0 | CB29: 442 | CC29: 1 | CD29: 0 | CE29: 0 | CF29: 0 | CG29: 0 | CH29: 3881 | CI29: 54877 | CJ29: 4067 | CK29: 1 | CL29: 0 | CM29: 0 | CN29: 0 | CO29: 0 | CP29: 0 | CQ29: 0 | CR29: 4067 | CS29: 1 | CT29: 0 | CU29: 0 | CV29: 12330 | CW29: 12330 | CX29: 2202913 | CY29: 2782162 | CZ29: 5736860 | DA29: 6069121 | DB29: 677310 | DC29: 677310 | DD29: 601753 | DE29: 601753 | DF29: 4381316 | DG29: 4411478 | DH29: 0 | DI29: 0 | DJ29: -3356669 | DK29: -3155119 | DL29: 0 | DM29: 0 | DN29: 0 | DO29: 0 | DP29: 2303710 | DQ29: 2535422 | DR29: 0 | DS29: 0 | DT29: 0 | DU29: 0 | DV29: 0 | DW29: 0 | DX29: 0 | DY29: 0 | DZ29: 0 | EA29: 0 | EB29: 0 | EC29: 0 | ED29: 0 | EE29: 0 | EF29: 0 | EG29: 0 | EH29: 0 | EI29: 0 | EJ29: 0 | EK29: 0 | EL29: 0 | EM29: 0 | EN29: 0 | EO29: 0 | EP29: 3433150 | EQ29: 3533699 | ER29: 3431422 | ES29: 3531971 | ET29: 0 | EU29: 0 | EV29: 1881561 | EW29: 908461 | EX29: 0 | EY29: 0 | EZ29: 0 | FA29: 0 | FB29: 0 | FC29: 0 | FD29: 0 | FE29: 0 | FF29: 0 | FG29: 0 | FH29: 932773 | FI29: 1717 | FJ29: 180195 | FK29: 1056823 | FL29: 0 | FM29: 0 | FN29: 156022 | FO29: 595957 | FP29: 0 | FQ29: 0 | FR29: 267262 | FS29: 913961 | FT29: 0 | FU29: 0 | FV29: 1728 | FW29: 1728 | FX29: 0 | FY29: 0 | FZ29: 13609 | GA29: 55052 | GB29: 3433150 | GC29: 3533699 | GD29: 5736860 | GE29: 6069121
A30: 20006 | B30: 0 | C30: 200002854 | D30: "JANUBSANOATMONTAJ" AJ | E30: 12 | F30: 1 | G30: 0 | H30: 1 | I30: 2021 | J30: 4 | K30: N | L30: 2 | M30: 30 | N30: 0 | O30: 44691.537 | P30: 29929641 | Q30: 35339106 | R30: 6544899 | S30: 11062046 | T30: 23384742 | U30: 24277060 | V30: 1162 | W30: 1162 | X30: 1162 | Y30: 1162 | Z30: 0 | AA30: 0 | AB30: 8928 | AC30: 8928 | AD30: 8928 | AE30: 8928 | AP30: 736366 | AQ30: 344680 | AV30: 24130036 | AW30: 24630668 | AX30: 8748785 | AY30: 9807735 | AZ30: 7310198 | BA30: 8702322 | BB30: 264441 | BC30: 0 | BD30: 1174146 | BE30: 1105413 | BH30: 0 | BI30: 0 | BL30: 75479688 | BM30: 92686231 | BP30: 61473743 | BQ30: 83951446 | BR30: 58898450 | BS30: 78468313 | BV30: 14978 | BW30: 40797 | BX30: 13002587 | BY30: 7558109 | BZ30: 775690 | CA30: 1626 | CB30: 4333 | CC30: 0 | CH30: 208357 | CI30: 1134253 | CJ30: 4950169 | CK30: 601917 | CN30: 4045428 | CO30: 597998 | CP30: 892109 | CQ30: 0 | CR30: 12632 | CS30: 3919 | CT30: 0 | CU30: 275000 | CV30: 0 | CW30: 0 | CX30: 89178642 | CY30: 103370883 | CZ30: 113308678 | DA30: 128001551 | DB30: 1633137 | DC30: 1633137 | DD30: 28485952 | DE30: 28485952 | DF30: 10635874 | DG30: 12431004 | DJ30: 1797941 | DK30: 1691711 | DP30: 42552904 | DQ30: 44241804 | EP30: 70755774 | EQ30: 83759747 | ER30: 70755774 | ES30: 83759747 | EV30: 52323795 | EW30: 78333978 | EX30: 50056498 | EY30: 76641872 | FA30: 0 | FH30: 16503347 | FI30: 3196471 | FJ30: 172410 | FK30: 689029 | FM30: 0 | FN30: 325134 | FO30: 233647 | FP30: 5834 | FQ30: 0 | FR30: 1018539 | FS30: 940042 | FV30: 0 | FW30: 0 | FZ30: 406715 | GA30: 366580 | GB30: 70755774 | GC30: 83759747 | GD30: 113308678 | GE30: 128001551
A31: 20006 | B31: 0 | C31: 200002854 | D31: "JANUBSANOATMONTAJ" AJ | E31: 12 | F31: 1 | G31: 0 | H31: 1 | I31: 2020 | J31: 4 | K31: N | L31: 2 | M31: 30 | N31: 0 | O31: 44303.46 | P31: 29326938 | Q31: 29929641 | R31: 2991007 | S31: 6544899 | T31: 26335931 | U31: 23384742 | V31: 1162 | W31: 1162 | X31: 1162 | Y31: 1162 | Z31: 0 | AA31: 0 | AB31: 8928 | AC31: 8928 | AD31: 8928 | AE31: 8928 | AQ31: 736366 | AV31: 26344859 | AW31: 24130036 | AX31: 7155635 | AY31: 8748785 | AZ31: 6757080 | BA31: 7310198 | BB31: 0 | BC31: 264441 | BD31: 398555 | BE31: 1174146 | BH31: 390 | BI31: 0 | BL31: 43636157 | BM31: 75479688 | BP31: 38220441 | BQ31: 61473743 | BS31: 58898450 | BV31: 11396 | BW31: 14978 | BX31: 0 | BY31: 13002587 | BZ31: 5010416 | CA31: 775690 | CB31: 4350 | CC31: 4333 | CH31: 389554 | CI31: 208357 | CJ31: 4518546 | CK31: 4950169 | CN31: 4495554 | CO31: 4045428 | CP31: 517 | CQ31: 892109 | CR31: 22475 | CS31: 12632 | CT31: 90000 | CU31: 0 | CV31: 0 | CW31: 0 | CX31: 55400728 | CY31: 89178642 | CZ31: 81745587 | DA31: 113308678 | DB31: 1633137 | DC31: 1633137 | DD31: 28485952 | DE31: 28485952 | DF31: 2853911 | DG31: 10635874 | DJ31: 7325796 | DK31: 1797941 | DP31: 40298796 | DQ31: 42552904 | EP31: 41446791 | EQ31: 70755774 | ER31: 41446791 | ES31: 70755774 | EV31: 34002810 | EW31: 52323795 | EY31: 50056498 | FA31: 0 | FH31: 0 | FI31: 16503347 | FJ31: 575371 | FK31: 172410 | FN31: 238386 | FO31: 325134 | FP31: 5834 | FQ31: 5834 | FR31: 1210463 | FS31: 1018539 | FV31: 0 | FW31: 0 | FZ31: 5413927 | GA31: 406715 | GB31: 41446791 | GC31: 70755774 | GD31: 81745587 | GE31: 113308678
A32: 20006 | B32: 0 | C32: 200002854 | D32: "JANUBSANOATMONTAJ" AJ | E32: 12 | F32: 1 | G32: 0 | H32: 1 | I32: 2019 | J32: 4 | K32: N | L32: 2 | M32: 30 | N32: 0 | O32: 44013.63 | P32: 4441262 | Q32: 29379938 | R32: 2929584 | S32: 2998957 | T32: 1511678 | U32: 26380981 | V32: 1162 | W32: 1162 | X32: 1162 | Y32: 1162 | Z32: 0 | AA32: 0 | AB32: 8590 | AC32: 8928 | AD32: 8590 | AE32: 8928 | AV32: 1520268 | AW32: 26389909 | AX32: 2036828 | AY32: 7165222 | AZ32: 1877340 | BA32: 6766667 | BB32: 0 | BD32: 159488 | BE32: 398555 | BH32: 840 | BI32: 390 | BL32: 18099356 | BM32: 43626495 | BP32: 2688471 | BQ32: 38210978 | BV32: 8385 | BW32: 11278 | BX32: 12784715 | BY32: 0 | CA32: 5011195 | CC32: 4350 | CH32: 2617785 | CI32: 388694 | CJ32: 2098015 | CK32: 4517319 | CN32: 1569845 | CO32: 4495554 | CP32: 22632 | CQ32: 517 | CR32: 505538 | CS32: 21248 | CU32: 90000 | CV32: 28802 | CW32: 0 | CX32: 22263841 | CY32: 55399426 | CZ32: 23784109 | DA32: 81789335 | DB32: 967500 | DC32: 1633137 | DE32: 28485952 | DF32: 654735 | DG32: 2853911 | DJ32: 3373120 | DK32: 7362340 | DP32: 4995355 | DQ32: 40335340 | EP32: 18788754 | EQ32: 41453995 | ER32: 17088754 | ES32: 41453995 | EV32: 13376998 | EW32: 34002090 | FH32: 324290 | FI32: 0 | FJ32: 1149512 | FK32: 585582 | FN32: 535810 | FO32: 238386 | FP32: 5903 | FQ32: 5834 | FR32: 586387 | FS32: 1207909 | FV32: 1700000 | FW32: 0 | FZ32: 1109854 | GA32: 5414194 | GB32: 18788754 | GC32: 41453995 | GD32: 23784109 | GE32: 81789335
A33: 20006 | B33: 0 | C33: 200002854 | D33: "JANUBSANOATMONTAJ" AJ | E33: 12 | F33: 1 | G33: 0 | H33: 1 | I33: 2018 | J33: 4 | K33: N | L33: 2 | M33: 30 | N33: 0 | O33: 43550.785 | P33: 3045346 | Q33: 4441262 | R33: 2325222 | S33: 2929584 | T33: 720124 | U33: 1511678 | V33: 1162 | W33: 1162 | X33: 1162 | Y33: 1162 | Z33: 0 | AA33: 0 | AB33: 8590 | AC33: 8590 | AD33: 8590 | AE33: 8590 | AP33: 132239 | AQ33: 0 | AV33: 860953 | AW33: 1520268 | AX33: 1058008 | AY33: 2036828 | AZ33: 784566 | BA33: 1877340 | BB33: 22119 | BC33: 0 | BD33: 251323 | BE33: 159488 | BH33: 3252 | BI33: 840 | BL33: 760728 | BM33: 18099356 | BP33: 616801 | BQ33: 2688471 | BV33: 10495 | BW33: 8385 | BX33: 55214 | BY33: 12784715 | BZ33: 1272 | CA33: 0 | CB33: 2956 | CC33: 0 | CH33: 73990 | CI33: 2617785 | CJ33: 100402 | CK33: 2098015 | CN33: 13947 | CO33: 1569845 | CP33: 83104 | CQ33: 22632 | CR33: 3351 | CS33: 505538 | CV33: 28802 | CW33: 28802 | CX33: 1951192 | CY33: 22263841 | CZ33: 2812145 | DA33: 23784109 | DB33: 967500 | DC33: 967500 | DF33: 634728 | DG33: 654735 | DJ33: 553598 | DK33: 3373120 | DP33: 2155826 | DQ33: 4995355 | EP33: 656319 | EQ33: 18788754 | ER33: 656319 | ES33: 17088754 | EV33: 109507 | EW33: 13376998 | FH33: 93206 | FI33: 324290 | FJ33: 209117 | FK33: 1149512 | FN33: 84624 | FO33: 535810 | FQ33: 5903 | FR33: 113091 | FS33: 586387 | FV33: 0 | FW33: 1700000 | FZ33: 46774 | GA33: 1109854 | GB33: 656319 | GC33: 18788754 | GD33: 2812145 | GE33: 23784109
A34: 20006 | B34: 0 | C34: 200049218 | D34: "O'ZELEKTROTERM" AJ | E34: 14 | F34: 1 | G34: 0 | H34: 1 | I34: 2021 | J34: 4 | K34: N | L34: 1 | M34: 30 | N34: 0 | O34: 44607.99 | P34: 416868 | Q34: 508883 | R34: 307213 | S34: 314492 | T34: 109655 | U34: 194391 | AB34: 160430 | AC34: 160430 | AD34: 20222 | AE34: 20222 | AF34: 140208 | AG34: 140208 | AV34: 270085 | AW34: 354821 | AX34: 262630 | AY34: 486657 | AZ34: 155975 | BA34: 379459 | BB34: 899 | BC34: 1619 | BD34: 11989 | BE34: 11989 | BF34: 93767 | BG34: 93590 | BH34: 161318 | BL34: 589706 | BM34: 336872 | BP34: 219390 | BQ34: 24368 | BT34: 295340 | BU34: 237310 | BW34: 231 | BX34: 68139 | BY34: 74963 | CH34: 6837 | CJ34: 277852 | CK34: 6983 | CN34: 277852 | CO34: 6983 | CX34: 1291506 | CY34: 830512 | CZ34: 1561591 | DA34: 1185333 | DB34: 643677 | DC34: 643677 | DF34: 51477 | DG34: 80547 | DJ34: 63101 | DK34: 63101 | DN34: 8377 | DO34: 315477 | DP34: 766632 | DQ34: 1102802 | EP34: 794959 | EQ34: 82531 | ER34: 794959 | ES34: 82531 | EV34: 2095 | EW34: 2273 | FH34: 700891 | FI34: 2746 | FJ34: 10137 | FK34: 32215 | FN34: 5816 | FO34: 5549 | FR34: 31180 | FZ34: 44840 | GA34: 39748 | GB34: 794959 | GC34: 82531 | GD34: 1561591 | GE34: 1185333
